<?xml version="1.0"?>
<robot name="planar_arm_robot">
    <link name="world" />
    <material name="red_translucent">
        <color rgba="1.0 0.0 0.0 0.2"/>
    </material>
    <material name="green">
        <color rgba="0.0 1.0 0.0 1.0"/>
    </material>
    <material name="blue">
        <color rgba="0.0 0.0 1.0 1.0"/>
    </material>
    <material name="grey">
        <color rgba="0.5 0.5 0.5 1.0"/>
    </material>

    <link name="base_link">
        <visual>
            <origin xyz="0.0 0.0 0.0" rpy="0 0 0"/>
            <geometry>
                <box size= "0.1 0.1 1.0"/>
            </geometry>
            <material name="red_translucent"/>
        </visual>
    </link>

    <link name="link_1">
        <visual>
            <origin xyz="0.2 0 0" rpy="0 0 0"/>     <!-- origin for link_1 defined at the edge of the link-->
            <geometry>
                <box size="0.4 0.05 0.005"/>        <!--length, breadth and height of the link -->
            </geometry>
            <material name="green"/>
        </visual>
        <collision>
            <origin xyz="0.2 0 0" rpy="0 0 0"/>
            <geometry>
                <mesh filename="package://planar_arm_robot_description/meshes/collision/link_1.stl" scale = "1 1 1"/>
            </geometry>
        </collision>
        <inertial>
            <origin xyz="0.2 0 0" rpy="0 0 0"/>
            <mass value="2.5"/>
            <inertia ixx="0.000526" ixy="0.0" ixz="0.0" iyy="0.033339" iyz="0.0" izz="0.033854"/>
        </inertial>
    </link>

    <link name="link_2">
        <visual>
            <origin xyz="0.2 0 0" rpy="0 0 0"/>     <!-- origin for link_2 also defined at the edge of the link.-->
            <geometry>
                <box size="0.4 0.05 0.005"/>        <!-- length, breadth and height of the link -->
            </geometry>
            <material name="blue"/>
        </visual>
        <collision>
            <origin xyz="0.2 0 0" rpy="0 0 0"/>
            <geometry>
                <mesh filename="package://planar_arm_robot_description/meshes/collision/link_2.stl" scale = "1 1 1"/>
            </geometry>
        </collision>
        <inertial>
            <origin xyz="0.2 0 0" rpy="0 0 0"/>
            <mass value="2.5"/>
            <inertia ixx="0.000526" ixy="0.0" ixz="0.0" iyy="0.033339" iyz="0.0" izz="0.033854"/>
        </inertial>        
    </link>

    <link name="end_effector_link">
        <visual>
            <origin xyz="0.005 0 0" rpy="0 0 0"/>     <!-- origin for end_effector.-->
            <geometry>
                <box size="0.01 0.02 0.05"/>        <!-- length, breadth and height of the link -->
            </geometry>
            <material name="grey"/>
        </visual>
        <collision>
            <origin xyz="0.005 0 0" rpy="0 0 0"/>
            <geometry>
                <mesh filename="package://planar_arm_robot_description/meshes/collision/end_effector.stl" scale = "1 1 1"/>
            </geometry>
        </collision>
        <inertial>
            <origin xyz="0 0 0" rpy="0 0 0"/>
            <mass value="2.5"/>
            <inertia ixx="0.000018" ixy="0.0" ixz="0.0" iyy="0.000016" iyz="0.0" izz="0.000003"/>
        </inertial>        
    </link>    

    <joint name="world_to_base_link" type="fixed">
        <origin xyz="0 0 0.5" rpy="0 0 0"/>
        <parent link="world"/>
        <child link="base_link"/>
    </joint>

    <joint name="base_link_to_link_1" type="revolute">
        <origin xyz="0.0 -0.05 0.5" rpy="1.5707963268 0.0 0.0"/>
        <parent link="base_link"/>
        <child link="link_1"/> 
        <axis xyz="0.0 0.0 1.0"/>
        <limit effort="10.0" velocity="2.0" lower="-3.14" upper="3.14"/>         
    </joint>

    <joint name="link_1_to_link_2" type="revolute">
        <origin xyz="0.4 0.0 0.0" rpy="0.0 0.0 0.0"/>
        <parent link="link_1"/>
        <child link="link_2"/>
        <axis xyz="0.0 0.0 1.0"/>
        <limit effort="10.0" velocity="2.0" lower="-3.14" upper="3.14"/> 
    </joint>

    <joint name="link_2_to_end_effector" type="revolute">
        <origin xyz="0.4 0.0 0.0" rpy="0.0 0.0 0.0"/>
        <parent link="link_2"/>
        <child link="end_effector_link"/>
        <axis xyz="1.0 0.0 0.0"/>
        <limit lower="-3.14" upper="3.14" effort="5.0" velocity="2.0"/>
    </joint>
</robot>